Workbook

Sheet COMPRAS E INV
A1: OJO NO USAR ESTE | B1: referencias | E1: PEDIDO SUR | F1: PEDIDO NORTE | H1: INVENT SUR mar 21 | I1: INVENT NTE | J1: FECHA VCMTO | K1: PRECIO COMPRA | L1: precio venta | M1: IVA | N1: PRECIO MALTERO | O1: % | P1: VR PEDIDO
A2: abre bocas Umbrella | E2: 0 | F2: 0 | G2: Pluss Dent GAB VEL | H2: 0 | I2: 0 | K2: =9288*1.19 -> 11052.72 | L2: 15000 | O2: =(L2/K2)-1 -> 0.357132 | P2: =K2*F2 -> 0
A3: Abreboca manual gancho DOBLE EXTREMO NEGRO | E3: 0 | F3: 0 | G3: IMPORTADA | I3: 8 | K3: 8746 | L3: 30000 | M3: 19 | O3: =(L3/K3)-1 -> 2.4301395 | P3: =K3*F3 -> 0
A4: Abreboca manual gancho DOBLE EXTREMO TRANSPARENTE | E4: 0 | F4: 0 | G4: IMPORTADA | I4: 50 | K4: =1962*2 -> 3924 | L4: 30000 | O4: =(L4/K4)-1 -> 6.6452599 | P4: =K4*F4 -> 0
A5: Abreboca manual gancho PEQUEÑO | E5: 0 | F5: 0 | G5: IMPORTADA | I5: 100 | K5: 1712 | L5: 10000 | O5: =(L5/K5)-1 -> 4.8411215 | P5: =K5*F5 -> 0
A6: Abreboca AZUL Y ROJO AMARILLO | E6: 0 | F6: 0 | G6: ELVER LOZANO BOGOTA | I6: rojo 1 azul 1 | K6: 4500 | L6: 12000 | O6: =(L6/K6)-1 -> 1.6666667 | P6: =K6*F6 -> 0
A7: abreboca Con retractor adulto | E7: 0 | F7: 0 | G7: UPEGUI | I7: BLANCO 43 NEGRO 10 | K7: 16900 | L7: 24000 | O7: =(L7/K7)-1 -> 0.42011834 | P7: =K7*F7 -> 0
A8: abreboca Con retractor PEDIATRICO | E8: 0 | F8: 0 | G8: UPEGUI | I8: 20 | K8: 16900 | L8: 24000 | O8: =(L8/K8)-1 -> 0.42011834 | P8: =K8*F8 -> 0
A9: Abreboca manual gancho GRANDE | E9: 0 | F9: 0 | G9: IMPORTADA | I9: 50 | K9: 1426.9789 | L9: 10000 | O9: =(L9/K9)-1 -> 6.0078119 | P9: =K9*F9 -> 0
A10: Abreboca sencillo adulto | B10: OXXI $ 11067 NISSI $7556 | E10: 20 | F10: 20 | G10: OXXI NISSI | I10: =8+16*5 -> 88 | K10: =9300*1.19/5 -> 2213.4 | L10: 8000 | O10: =(L10/K10)-1 -> 2.614349 | P10: =K10*F10 -> 44268
A11: Abreboca sencillo niño | B11: OXXI $ 11067 NISSI $7557 | E11: 10 | F11: 0 | G11: OXXI NISSI | I11: 26 | K11: =9300*1.19/5 -> 2213.4 | L11: 8000 | O11: =(L11/K11)-1 -> 2.614349 | P11: =K11*F11 -> 0
A12: abreboca sin retractor | E12: 0 | F12: 0 | G12: UPEGUI | I12: 10 | K12: 16900 | L12: 24000 | O12: =(L12/K12)-1 -> 0.42011834 | P12: =K12*F12 -> 0
A13: abrebocas aclaramiento tipo optragate | E13: 0 | F13: 0 | G13: IMPORTADA | I13: 58 | K13: 4602 | L13: 12000 | O13: =(L13/K13)-1 -> 1.6075619 | P13: =K13*F13 -> 0
A14: Accufilm Papel de articular aqua film x 280 tiras | E14: 0 | F14: 0 | G14: La muela miguel | I14: 1 | K14: =65000/200 -> 325 | L14: 800 | O14: =(L14/K14)-1 -> 1.4615385 | P14: =K14*F14 -> 0
A15: Accufilm Papel de articular CIRENE aqua film x 280 tiras | E15: 0 | F15: 0 | G15: La muela miguel | K15: 65000 | L15: 105000 | N15: 90000 | O15: =(L15/K15)-1 -> 0.61538462 | P15: =K15*F15 -> 0
A16: Aceite 3 en 1 | E16: 0 | G16: CENTRO HOYOSTOOL | K16: =3200*1.19 -> 3808 | L16: 6000 | O16: =(L16/K16)-1 -> 0.57563025 | P16: =K16*F16 -> 0
A17: aceite lubricante - pieza de mano Dental handpiece 300ml | E17: 0 | F17: 0 | G17: DTM | K17: 28000 | L17: 48000 | N17: 38000 | O17: =(L17/K17)-1 -> 0.71428571
A18: aceite lubricante - pieza de mano Dental handpiece 550ml | E18: 0 | F18: 0 | G18: DTM | K18: 35000 | L18: 54000 | N18: 44000 | O18: =(L18/K18)-1 -> 0.54285714
A19: aceite lubricante - pieza de mano PANASPRAY PLUS NSK 480ML | B19: NSK | E19: 0 | F19: 0 | G19: LA MUELA | I19: 10 | J19: 45717 | K19: =121849*1.19 -> 145000.31 | L19: 178000 | N19: 168000 | O19: =(L19/K19)-1 -> 0.22758358 | P19: =K19*F19 -> 0
A20: aceite lubricante - pieza de mano WYH 400ML | B20: euro $96250 | G20: MASDENTAL EURODENT | I20: 0 | K20: 116000 | L20: 145000 | N20: 120000 | O20: =(L20/K20)-1 -> 0.25 | P20: =K20*F20 -> 0
A21: Aceite lubricante Bendechk 300ml | E21: 0 | F21: 0 | G21: makrodent DTM | K21: 35000 | L21: 48000 | O21: =(L21/K21)-1 -> 0.37142857 | P21: =K21*F21 -> 0
A22: aceite lubricante de piezas digixpray 240ml | E22: 0 | F22: 0 | G22: muela | K22: 24850 | L22: 48000 | M22: iva | N22: 34000
A23: Aceite lubricante en Spray 200 ml- KAVO | C23: AGOTADO | E23: 0 | F23: 0 | G23: Pluss Dent GAB VEL | H23: 0 | I23: 0 | K23: 49504 | L23: 65000 | O23: =(L23/K23)-1 -> 0.31302521 | P23: =K23*F23 -> 0
A24: aceite lubricante pequeño - pieza de mano 50 ml | E24: 0 | G24: RAMON | K24: 7400 | L24: 12000 | O24: =(L24/K24)-1 -> 0.62162162 | P24: =K24*F24 -> 0
A25: Aceite lubricante Quiruspray 200 cc - pieza de mano | B25: ramon $29.500 aquiles $24.871 | E25: 0 | G25: RAMON AQUILES | K25: =24789.92*1.19 -> 29500.005 | L25: 39000 | O25: =(L25/K25)-1 -> 0.32203368 | P25: =K25*F25 -> 0
A26: Aceite lubricante Universal en Spray 250 ml- Adensys | E26: 0 | F26: 0 | G26: Pluss Dent GAB VEL | H26: 0 | I26: 10 | J26: 46174 | K26: =50500*1.19 -> 60095 | L26: 76000 | N26: 65000 | O26: =(L26/K26)-1 -> 0.26466428 | P26: =K26*F27 -> 0
A27: Aceite LUBRICANTE X200 ML Maquira | E27: 0 | F27: 0 | G27: SOCCIDENTALES | I27: 0 | J27: 46174 | K27: =26000*1.19 -> 30940 | L27: 55000 | O27: =(L27/K27)-1 -> 0.77763413 | P27: =K27*#REF! -> #REF!
A28: Aceite super lubry 50ml | E28: 0 | F28: 0 | G28: AQUILES | I28: 0 | J28: 46174 | K28: 7500 | L28: 12000 | O28: =(L28/K28)-1 -> 0.6 | P28: =K28*F28 -> 0
A29: acetato lamina rosada 0.6 | E29: 0 | G29: RAMON | K29: 1800 | L29: 3500 | O29: =(L29/K29)-1 -> 0.94444444 | P29: =K29*F29 -> 0
A30: acetato rigido ACE | E30: 0 | G30: RAMON | K30: 6400 | L30: 9000 | O30: =(L30/K30)-1 -> 0.40625 | P30: =K30*F30 -> 0
A31: acido clorhidrico removedor de manchas opalustre FGM whiteness RM 6% | B31: antioq $95200 soccid $ 80,206 plus $79968 | E31: 0 | F31: 0 | G31: FGM soccident | I31: 0 | J31: 46082 | K31: =100000*0.8*1.19 -> 95200 | L31: 145000 | O31: =(L31/K31)-1 -> 0.52310924 | P31: =K31*F31 -> 0
A32: Acido desmineralizante 2.5 coltene | B32: ACIDO | E32: 0 | F32: 0 | G32: Ultradental | I32: 0 | K32: 10868 | L32: 18000 | O32: =(L32/K32)-1 -> 0.6562385 | P32: =K32*F32 -> 0
A33: acido desmineralizante 2.5 Densell 12g 35% | B33: ACIDO | E33: 0 | F33: 0 | G33: La muela - ramon | J33: 46478 | K33: 12000 | L33: 20000 | M33: exc | N33: 18000 | O33: =(L33/K33)-1 -> 0.66666667 | P33: =K33*F33 -> 0
A34: Acido desmineralizante 35% ultradent 1.2ml | B34: ACIDO | E34: 2 | F34: 0 | G34: Gabriel Vel pluss | H34: 2 | I34: 3 | K34: 13272 | L34: 22000 | O34: =(L34/K34)-1 -> 0.65762508 | P34: =K34*F34 -> 0
A35: acido desmineralizante 37% fosforico MAQUIRA 2.5 | B35: ACIDO | C35: PRECIO MAYO 20 | D35: =(6500*1.19)/3 -> 2578.3333 | E35: 0 | F35: 0 | G35: RAMON CLAUDIA SOCCIDENTALES | J35: 45962 | K35: =(11654*1.19)/3 -> 4622.7533 | L35: 13000 | M35: EXC | O35: =(L35/K35)-1 -> 1.8121769 | P35: =K35*F35 -> 0
A36: acido desmineralizante angelus 3 grs | B36: ACIDO | E36: 0 | F36: 0 | G36: CLAUDIA | I36: 0 | K36: 2000 | L36: 10000 | O36: =(L36/K36)-1 -> 4 | P36: =K36*F36 -> 0
A37: Acido desmineralizante FGM condac 12.5 ML | B37: ACIDO promo antoq $24375 SOCCIDEN 20825 plus20000 | E37: 0 | F37: 0 | G37: FGM soccident | I37: 0 | J37: 45992 | K37: =32500*0.8 -> 26000 | L37: 35000 | M37: exc | O37: =(L37/K37)-1 -> 0.34615385 | P37: =K37*F37 -> 0
A38: Acido Desmineralizante proquident 10ML jumbo | B38: ACIDO | G38: PROQUIDENT | I38: 2 | J38: 46844 | K38: 14173 | L38: 24000 | O38: =(L38/K38)-1 -> 0.69336062 | P38: =K38*#REF! -> #REF!
A39: Acido Desmineralizante Select H V ETCH 5ML Bisco | B39: promo $48.450 mayo/25 | G39: JULVIDENT bisco | I39: 11 | J39: 46447 | K39: 54000 | L39: 68000 | M39: EXC | O39: =(L39/K39)-1 -> 0.25925926 | P39: =K39*F39 -> 0
A40: Acido desmineralizante SUPER ETCH SDI 12 gm | B40: ACIDO | E40: 0 | F40: 0 | G40: ABRAHAM | I40: 6 | J40: 46296 | K40: 33800 | L40: 42500 | M40: exc | O40: =(L40/K40)-1 -> 0.25739645 | P40: =K40*F40 -> 0
...

Sheet OXXI
B1: referencias | E1: PEDIDO SUR | F1: PEDIDO NORTE | G1: TOTAL
A2: Abreboca sencillo adulto | B2: OXXI $ 11067 NISSI $7556 | E2: 20 | F2: 20 | G2: 40 | H2: =G2*7556 -> 302240
A3: Abreboca sencillo niño | B3: OXXI $ 11067 NISSI $7557 | E3: 10 | F3: 0 | G3: 10 | H3: =10*7557 -> 75570
A4: CAJA RETENEDORA PEQUEÑA | B4: oxxi $1220 orhto prof $1071 | E4: 100 | F4: 200 | G4: 300 | H4: =300*1071 -> 321300

Sheet THERACEM
A1: THERACEM
C3: FECHA VCT | D3: LOTE
A4: NORTE | B4: 9 | C4: 46021 | D4: 2400004102
A5: NORTE | B5: 1 | C5: 45931 | D5: 2400002387
A6: CESAR | B6: 6 | C6: 45931 | D6: 2400002664
A7: SUR | B7: 4 | C7: 45935 | D7: 2400002664
A8: SUR | B8: 1 | C8: 45934 | D8: 2400002387
A12: THERACEM
C14: FECHA VCT | D14: LOTE
A15: NORTE | B15: 9 | C15: 46021 | D15: 2400004102
A16: NORTE | B16: 2 | C16: 45931 | D16: 2400002387
B17: 10 | C17: 45931 | D17: 2400002664

Sheet FECHA VTO CORTA
A2: PRODUCTO | B2: PROVEDOR | D2: FECHA DE VENCIMIENTO | E2: COSTO | F2: VENTA | G2: PRECIO PROMO | H2: PRECIO MALETERO
A3: Adhesivo bond 2.1 4ml maquira | B3: SOCCIDEN $22000 | D3: 45901 | E3: 24000 | F3: 44000
A4: Adhesivo coltene COAT BOND | B4: promo nov $72348 | D4: 46082 | E4: 87000 | F4: 105000
A5: Barrera Gingival Max Dam Jeringa 2 g Maquira | B5: COMPRE 17600 | C5: PRECIO 20 MAYO | D5: 46023 | E5: 21120 | F5: 38000
A6: Barrera Gingival Top Dam 2 g FGM | B6: SOCCID $19700 X 50 | C6: Barrera | D6: 46054 | E6: 19200 | F6: 32000
A7: cemento temporal Applic 2g maquira x 2 jeringas | D7: 45839 | E7: =38104/2 -> 19052 | F7: 34000
A8: CHOISE Try-in paste traslucido 2g bisco Probador | C8: promo $85 | D8: 45839 | E8: =86000 -> 86000 | F8: 105000
A9: fix RESINA ortodoncia 2.5ml | B9: ortho $35000 | D9: 45992 | E9: 47430 | F9: 78000
A10: FUJI 1 CEMENTANTE BLANCO LETRA ROJA | B10: masdental $158900 la muela promo $121500 | D10: 45962 | E10: 121500 | F10: 165000
A11: FUJI 2 RESTAURATIVO BLANCO CON VERDE AUTO | B11: promo $121500 | D11: 46113 | E11: 121500 | F11: 165000
A12: orthocem resina ortodoncia FGM | B12: antioq $45000 soccid $ 47000 plus $68000 | D12: 45809 | E12: =85000*0.8 -> 68000 | F12: 85000
A13: Resina Charisma jeringa 4gr BL | C13: ALTA ESTETICA | D13: 45870 | E13: 180000 | F13: 260000
A14: Thera CEM Bisco | B14: promo 208200 | C14: en promo se compro a $289167 | D14: 1/12/2025 10-2025 | E14: 315455 | F14: 390000
A15: PARACORE | D15: 1 21-08-2025 2 1-02-2025 | E15: 350000 | F15: 290000

Sheet TEMPO NORTE PEDIDO BIODENTALES
A1: pedi junio 28 | B1: referencias | E1: PEDIDO SUR | F1: PEDIDO NORTE | H1: INVENT SUR mar 21 | I1: INVENT NTE | J1: FECHA VCMTO | K1: PRECIO COMPRA | L1: precio venta
A2: ARTICULADOR plastico PASTA transparenteñ | F2: 0 | G2: biodentales Monica jorge - aquiles | K2: 3374 | L2: 6000
A3: Cera azul WHIPMIX PAQUETE X 20 BARRAS VTA UNIDAD | F3: 0 | G3: Biodentales | I3: 20 | K3: =22950*1.19/20 -> 1365.525 | L3: 2000
A4: Cera Blanca marfil WHIPMIX PAQUETE X 120 BARRAS | F4: 0 | G4: Biodentales | I4: 20 | K4: =(81855*1.19)/120 -> 811.72875 | L4: 2000
A5: Cera Blanca marfil WHIPMIX PAQUETE X 20 BARRAS | F5: 0 | G5: Biodentales | I5: 20 | K5: =22950*1.19/20 -> 1365.525 | L5: 2000
A6: Cera rojo WHIPMIX PAQUETE X 20 BARRAS VTA UNIDAD | F6: 0 | G6: Biodentales | I6: 20 | K6: =22950*1.19/20 -> 1365.525 | L6: 2000
A7: Cera verde WHIPMIX PAQUETE X 20 BARRAS VTA UNIDAD | F7: 0 | G7: Biodentales | I7: 20 | J7: 46722 | K7: =22950*1.19/20 -> 1365.525 | L7: 2000
A8: cerafina x 60 | F8: 0 | G8: monica - ramon biodentales | J8: 45992 | K8: =4563*1.19 -> 5429.97 | L8: 8000
A9: cerafina x 90 | F9: 0 | G9: monica - ramon biodentales | K9: =7677*1.19 -> 9135.63 | L9: 12000
A10: CUBETA PLASTICA IMPRESION PARA NIÑO JUEGO X6 | F10: 0 | G10: biodentales-NATURAL SISTEM | I10: 8 | K10: =11640*1.19 -> 13851.6 | L10: 20000
A11: Fresa carburo 1/2 HP Tallo largo | C11: CARBURO | F11: 0 | G11: biodentaleS MDS masterdent ramon | K11: =34290*1.19/5 -> 8161.02 | L11: 18000
A12: fresa carburo 245 FG Tallo Corto pediatrica | C12: CARBURO | F12: 0 | G12: biodentaleS MDS ramon | K12: =34290*1.19/5 -> 8161.02 | L12: 18000
A13: fresa carburo 330 FG Tallo Corto pediatrica | C13: CARBURO | F13: 0 | G13: biodentaleS MDS ramon | K13: =34290*1.19/5 -> 8161.02 | L13: 18000
A14: fresa carburo 331 FG Tallo Corto | C14: CARBURO | F14: 0 | G14: biodentaleS MDS ramon | K14: =34290*1.19/5 -> 8161.02 | L14: 18000
A15: fresa carburo 331 L FG Tallo Corto | C15: CARBURO | F15: 0 | G15: biodentaleS MDS ramon | K15: =34290*1.19/5 -> 8161.02 | L15: 18000
A16: FRESA CARBURO FG 700 Tallo Corto | C16: CARBURO | F16: 0 | G16: biodentaleS MDS ramon | K16: =34290*1.19/5 -> 8161.02 | L16: 18000
A17: FRESA CARBURO FG 701 Tallo Corto | C17: CARBURO | F17: 0 | G17: biodentaleS MDS ramon | K17: =34290*1.19/5 -> 8161.02 | L17: 18000
A18: FRESA CARBURO FG 702 Tallo Corto | B18: 245034 | C18: CARBURO | F18: 0 | G18: biodentaleS MDS ramon | K18: =34290*1.19/5 -> 8161.02 | L18: 18000
A19: FRESA CARBURO FG 703 Tallo Corto | B19: 245035 | C19: CARBURO | F19: 0 | G19: biodentaleS MDS ramon | K19: =34290*1.19/5 -> 8161.02 | L19: 18000
A20: FRESA CARBURO HP 700 Tallo Largo | B20: 245032 | C20: CARBURO | F20: 0 | G20: biodentaleS MDS masterdent ramon | K20: 6378 | L20: 18000
A21: FRESA CARBURO HP 701 Tallo Largo | B21: 245033 | C21: CARBURO | F21: 0 | G21: biodentaleS MDS masterdent ramon | K21: 6378 | L21: 18000
A22: FRESA CARBURO HP 702 Tallo Largo | B22: 245034 | C22: CARBURO | F22: 0 | G22: biodentaleS MDS masterdent ramon | K22: 6378 | L22: 18000
A23: FRESA CARBURO HP 703 Tallo Largo | B23: 245035 | C23: CARBURO | F23: 0 | G23: biodentaleS MDS masterdent ramon | K23: 6378 | L23: 18000
A24: fresa carburo N° 1 FG Tallo Corto | C24: CARBURO | F24: 0 | G24: biodentaleS MDS ramon | K24: =34290*1.19/5 -> 8161.02 | L24: 18000
A25: fresa carburo N° 1 HP Tallo largo | C25: CARBURO | F25: 0 | G25: biodentaleS MDS masterdent ramon | K25: =34290*1.19/5 -> 8161.02 | L25: 18000
A26: fresa carburo N° 1/2 FG Tallo Corto pediatrica | C26: CARBURO | F26: 0 | G26: biodentaleS MDS ramon | K26: =34290*1.19/5 -> 8161.02 | L26: 18000
A27: fresa carburo N° 1/4 FG Tallo Corto pediatrica | C27: CARBURO | F27: 0 | G27: biodentaleS MDS ramon | K27: =34290*1.19/5 -> 8161.02 | L27: 18000
A28: fresa carburo N° 1P FG Tallo Corto pediatrica | C28: CARBURO | F28: 0 | G28: biodentaleS MDS ramon | K28: =34290*1.19/5 -> 8161.02 | L28: 18000
A29: fresa carburo N° 2 FG Tallo Corto | C29: CARBURO | F29: 0 | G29: biodentaleS MDS ramon | K29: =34290*1.19/5 -> 8161.02 | L29: 18000
A30: fresa carburo N° 2P FG Tallo Corto pediatrica | C30: CARBURO | F30: 0 | G30: biodentaleS MDS ramon | K30: =34290*1.19/5 -> 8161.02 | L30: 18000
A31: fresa carburo N° 3 FG Tallo Corto | C31: CARBURO | F31: 0 | G31: biodentaleS MDS ramon | K31: =34290*1.19/5 -> 8161.02 | L31: 18000
A32: fresa carburo N° 3 HP Tallo largo | C32: CARBURO | F32: 0 | G32: biodentaleS MDS masterdent ramon | K32: =34290*1.19/5 -> 8161.02 | L32: 18000
A33: fresa carburo N° 3P FG Tallo Corto pediatrica | C33: CARBURO | F33: 0 | G33: biodentaleS MDS ramon | K33: =34290*1.19/5 -> 8161.02 | L33: 18000
A34: fresa carburo N° 4 FG Tallo Corto | C34: CARBURO | F34: 0 | G34: biodentaleS MDS ramon | K34: =34290*1.19/5 -> 8161.02 | L34: 18000
A35: fresa carburo N° 4 HP tallo largo | B35: 245039 | C35: CARBURO | F35: 0 | G35: biodentaleS MDS masterdent ramon | K35: 6378 | L35: 18000
A36: fresa carburo N° 5 FG Tallo Corto | C36: CARBURO | F36: 0 | G36: biodentaleS MDS ramon | K36: =34290*1.19/5 -> 8161.02 | L36: 18000
A37: fresa carburo N° 5 HP tallo largo | C37: CARBURO | F37: 0 | G37: biodentaleS MDS masterdent ramon | K37: =34290*1.19/5 -> 8161.02 | L37: 18000
A38: fresa carburo N° 6 FG Tallo Corto | C38: CARBURO | F38: 0 | G38: biodentaleS MDS ramon | K38: =34290*1.19/5 -> 8161.02 | L38: 18000
A39: fresa carburo N° 6 HP tallo largo | B39: 245041 | C39: CARBURO | F39: 0 | G39: biodentaleS MDS masterdent ramon | K39: 6378 | L39: 18000
A40: fresa carburo N° 7 FG tallo corto | C40: CARBURO | F40: 0 | G40: biodentaleS MDS ramon | K40: =34290*1.19/5 -> 8161.02 | L40: 18000
...

Sheet COPIA NORTE 28 JUN 
B1: referencias | E1: PEDIDO SUR | F1: PEDIDO NORTE | H1: INVENT SUR mar 21 | I1: INVENT NTE | J1: FECHA VCMTO | K1: PRECIO COMPRA | L1: precio venta | M1: IVA | N1: PRECIO MALTERO | O1: % | P1: VR PEDIDO
A2: abre bocas Umbrella | E2: 0 | F2: 0 | G2: Pluss Dent GAB VEL | H2: 0 | I2: 0 | K2: =9288*1.19 -> 11052.72 | L2: 15000 | O2: =(L2/K2)-1 -> 0.357132 | P2: =K2*F2 -> 0
A3: Abreboca manual gancho DOBLE EXTREMO NEGRO | E3: 0 | F3: 0 | G3: IMPORTADA | I3: 8 | K3: 8746 | L3: 30000 | M3: 19 | O3: =(L3/K3)-1 -> 2.4301395 | P3: =K3*F3 -> 0
A4: Abreboca manual gancho DOBLE EXTREMO TRANSPARENTE | E4: 0 | F4: 0 | G4: IMPORTADA | I4: 50 | K4: =1962*2 -> 3924 | L4: 30000 | O4: =(L4/K4)-1 -> 6.6452599 | P4: =K4*F4 -> 0
A5: Abreboca manual gancho PEQUEÑO | E5: 0 | F5: 0 | G5: IMPORTADA | I5: 100 | K5: 1712 | L5: 10000 | O5: =(L5/K5)-1 -> 4.8411215 | P5: =K5*F5 -> 0
A6: Abreboca AZUL Y ROJO AMARILLO | E6: 0 | F6: 0 | G6: ELVER LOZANO BOGOTA | I6: rojo 1 azul 1 | K6: 4500 | L6: 12000 | O6: =(L6/K6)-1 -> 1.6666667 | P6: =K6*F6 -> 0
A7: abreboca Con retractor adulto | E7: 0 | F7: 0 | G7: UPEGUI | I7: BLANCO 43 NEGRO 10 | K7: 16900 | L7: 24000 | O7: =(L7/K7)-1 -> 0.42011834 | P7: =K7*F7 -> 0
A8: abreboca Con retractor PEDIATRICO | E8: 0 | F8: 0 | G8: UPEGUI | I8: 20 | K8: 16900 | L8: 24000 | O8: =(L8/K8)-1 -> 0.42011834 | P8: =K8*F8 -> 0
A9: Abreboca manual gancho GRANDE | E9: 0 | F9: 0 | G9: IMPORTADA | I9: 50 | K9: 1426.9789 | L9: 10000 | O9: =(L9/K9)-1 -> 6.0078119 | P9: =K9*F9 -> 0
A10: Abreboca sencillo adulto | B10: OXXI $ 11067 NISSI $7556 | E10: 20 | F10: 20 | G10: OXXI NISSI | I10: =8+16*5 -> 88 | K10: =9300*1.19/5 -> 2213.4 | L10: 8000 | O10: =(L10/K10)-1 -> 2.614349 | P10: =K10*F10 -> 44268
A11: Abreboca sencillo niño | B11: OXXI $ 11067 NISSI $7557 | E11: 10 | F11: 0 | G11: OXXI NISSI | I11: 26 | K11: =9300*1.19/5 -> 2213.4 | L11: 8000 | O11: =(L11/K11)-1 -> 2.614349 | P11: =K11*F11 -> 0
A12: abreboca sin retractor | E12: 0 | F12: 0 | G12: UPEGUI | I12: 10 | K12: 16900 | L12: 24000 | O12: =(L12/K12)-1 -> 0.42011834 | P12: =K12*F12 -> 0
A13: abrebocas aclaramiento tipo optragate | E13: 0 | F13: 0 | G13: IMPORTADA | I13: 58 | K13: 4602 | L13: 12000 | O13: =(L13/K13)-1 -> 1.6075619 | P13: =K13*F13 -> 0
A14: Accufilm Papel de articular aqua film x 280 tiras | E14: 0 | F14: 0 | G14: La muela miguel | I14: 1 | K14: =65000/200 -> 325 | L14: 800 | O14: =(L14/K14)-1 -> 1.4615385 | P14: =K14*F14 -> 0
A15: Accufilm Papel de articular CIRENE aqua film x 280 tiras | E15: 0 | F15: 0 | G15: La muela miguel | K15: 65000 | L15: 105000 | N15: 90000 | O15: =(L15/K15)-1 -> 0.61538462 | P15: =K15*F15 -> 0
A16: Aceite 3 en 1 | E16: 0 | G16: CENTRO HOYOSTOOL | K16: =3200*1.19 -> 3808 | L16: 6000 | O16: =(L16/K16)-1 -> 0.57563025 | P16: =K16*F16 -> 0
A17: aceite lubricante - pieza de mano Dental handpiece 300ml | E17: 0 | F17: 0 | G17: DTM | K17: 28000 | L17: 48000 | N17: 38000 | O17: =(L17/K17)-1 -> 0.71428571
A18: aceite lubricante - pieza de mano Dental handpiece 550ml | E18: 0 | F18: 0 | G18: DTM | K18: 35000 | L18: 54000 | N18: 44000 | O18: =(L18/K18)-1 -> 0.54285714
A19: aceite lubricante - pieza de mano PANASPRAY PLUS NSK 480ML | B19: NSK | E19: 0 | F19: 0 | G19: LA MUELA | I19: 10 | J19: 45717 | K19: =121849*1.19 -> 145000.31 | L19: 178000 | N19: 168000 | O19: =(L19/K19)-1 -> 0.22758358 | P19: =K19*F19 -> 0
A20: aceite lubricante - pieza de mano WYH 400ML | B20: euro $96250 | G20: MASDENTAL EURODENT | I20: 0 | K20: 116000 | L20: 145000 | N20: 120000 | O20: =(L20/K20)-1 -> 0.25 | P20: =K20*F20 -> 0
A21: Aceite lubricante Bendechk 300ml | E21: 0 | F21: 0 | G21: makrodent DTM | K21: 35000 | L21: 48000 | O21: =(L21/K21)-1 -> 0.37142857 | P21: =K21*F21 -> 0
A22: aceite lubricante de piezas digixpray 240ml | E22: 0 | F22: 0 | G22: muela | K22: 24850 | L22: 48000 | M22: iva | N22: 34000
A23: Aceite lubricante en Spray 200 ml- KAVO | C23: AGOTADO | E23: 0 | F23: 0 | G23: Pluss Dent GAB VEL | H23: 0 | I23: 0 | K23: 49504 | L23: 65000 | O23: =(L23/K23)-1 -> 0.31302521 | P23: =K23*F23 -> 0
A24: aceite lubricante pequeño - pieza de mano 50 ml | E24: 0 | G24: RAMON | K24: 7400 | L24: 12000 | O24: =(L24/K24)-1 -> 0.62162162 | P24: =K24*F24 -> 0
A25: Aceite lubricante Quiruspray 200 cc - pieza de mano | B25: ramon $29.500 aquiles $24.871 | E25: 0 | G25: RAMON AQUILES | K25: =24789.92*1.19 -> 29500.005 | L25: 39000 | O25: =(L25/K25)-1 -> 0.32203368 | P25: =K25*F25 -> 0
A26: Aceite lubricante Universal en Spray 250 ml- Adensys | E26: 0 | F26: 0 | G26: Pluss Dent GAB VEL | H26: 0 | I26: 10 | J26: 46174 | K26: =50500*1.19 -> 60095 | L26: 76000 | N26: 65000 | O26: =(L26/K26)-1 -> 0.26466428 | P26: =K26*F27 -> 0
A27: Aceite LUBRICANTE X200 ML Maquira | E27: 0 | F27: 0 | G27: SOCCIDENTALES | I27: 0 | J27: 46174 | K27: =26000*1.19 -> 30940 | L27: 55000 | O27: =(L27/K27)-1 -> 0.77763413 | P27: =K27*#REF! -> #REF!
A28: Aceite super lubry 50ml | E28: 0 | F28: 0 | G28: AQUILES | I28: 0 | J28: 46174 | K28: 7500 | L28: 12000 | O28: =(L28/K28)-1 -> 0.6 | P28: =K28*F28 -> 0
A29: acetato lamina rosada 0.6 | E29: 0 | G29: RAMON | K29: 1800 | L29: 3500 | O29: =(L29/K29)-1 -> 0.94444444 | P29: =K29*F29 -> 0
A30: acetato rigido ACE | E30: 0 | G30: RAMON | K30: 6400 | L30: 9000 | O30: =(L30/K30)-1 -> 0.40625 | P30: =K30*F30 -> 0
A31: acido clorhidrico removedor de manchas opalustre FGM whiteness RM 6% | B31: antioq $95200 soccid $ 80,206 plus $79968 | E31: 0 | F31: 0 | G31: FGM soccident | I31: 0 | J31: 46082 | K31: =100000*0.8*1.19 -> 95200 | L31: 145000 | O31: =(L31/K31)-1 -> 0.52310924 | P31: =K31*F31 -> 0
A32: Acido desmineralizante 2.5 coltene | B32: ACIDO | E32: 0 | F32: 0 | G32: Ultradental | I32: 0 | K32: 10868 | L32: 18000 | O32: =(L32/K32)-1 -> 0.6562385 | P32: =K32*F32 -> 0
A33: acido desmineralizante 2.5 Densell 12g 35% | B33: ACIDO | E33: 0 | F33: 0 | G33: La muela - ramon | J33: 46478 | K33: 12000 | L33: 20000 | M33: exc | N33: 18000 | O33: =(L33/K33)-1 -> 0.66666667 | P33: =K33*F33 -> 0
A34: Acido desmineralizante 35% ultradent 1.2ml | B34: ACIDO | E34: 2 | F34: 0 | G34: Gabriel Vel pluss | H34: 2 | I34: 3 | K34: 13272 | L34: 22000 | O34: =(L34/K34)-1 -> 0.65762508 | P34: =K34*F34 -> 0
A35: acido desmineralizante 37% fosforico MAQUIRA 2.5 | B35: ACIDO | C35: PRECIO MAYO 20 | D35: =(6500*1.19)/3 -> 2578.3333 | E35: 0 | F35: 0 | G35: RAMON CLAUDIA SOCCIDENTALES | J35: 45962 | K35: =(11654*1.19)/3 -> 4622.7533 | L35: 13000 | M35: EXC | O35: =(L35/K35)-1 -> 1.8121769 | P35: =K35*F35 -> 0
A36: acido desmineralizante angelus 3 grs | B36: ACIDO | E36: 0 | F36: 0 | G36: CLAUDIA | I36: 0 | K36: 2000 | L36: 10000 | O36: =(L36/K36)-1 -> 4 | P36: =K36*F36 -> 0
A37: Acido desmineralizante FGM condac 12.5 ML | B37: ACIDO promo antoq $24375 SOCCIDEN 20825 plus20000 | E37: 0 | F37: 0 | G37: FGM soccident | I37: 0 | J37: 45992 | K37: =32500*0.8 -> 26000 | L37: 35000 | M37: exc | O37: =(L37/K37)-1 -> 0.34615385 | P37: =K37*F37 -> 0
A38: Acido Desmineralizante proquident 10ML jumbo | B38: ACIDO | G38: PROQUIDENT | I38: 2 | J38: 46844 | K38: 14173 | L38: 24000 | O38: =(L38/K38)-1 -> 0.69336062 | P38: =K38*#REF! -> #REF!
A39: Acido Desmineralizante Select H V ETCH 5ML Bisco | B39: promo $48.450 mayo/25 | G39: JULVIDENT bisco | I39: 11 | J39: 46447 | K39: 54000 | L39: 68000 | M39: EXC | O39: =(L39/K39)-1 -> 0.25925926 | P39: =K39*F39 -> 0
A40: Acido desmineralizante SUPER ETCH SDI 12 gm | B40: ACIDO | F40: 0 | G40: ABRAHAM | J40: 46296 | K40: 33800 | L40: 42500 | M40: exc | O40: =(L40/K40)-1 -> 0.25739645 | P40: =K40*F40 -> 0
...

Sheet Hoja 692
B2: DYMA | D2: FECHA:
C5: INVENTARIO | D5: PEDIDO
B6: Cubetas Plasticas de Colores surtidas paquete x 3 p
B7: Dientes de Endodoncia D ENDO 11 23 25 36
B8: dientes de ivorina
B9: dientes de NISSI
B10: Espatula Plastica de Alginato Zendent
B11: Espatula plastica para alginato (NO NARANJA NI VERDE)
B12: formaletas plasticas L
B13: formaletas plasticas M
B14: formaletas plasticas S
B15: FOSFATO DE ZINC oxifosfato LEE SMITH
B16: macro modelo plastico
B17: medidor de alginato
... B43: VERABOND II LABORATORIO

Sheet COPIA SUR JUN 25
B1: referencias | E1: PEDIDO SUR | F1: PEDIDO NORTE | H1: INVENT SUR mar 21 | I1: INVENT NTE | J1: FECHA VCMTO | K1: PRECIO COMPRA | L1: precio venta | M1: IVA | N1: PRECIO MALTERO | O1: % | P1: VR PEDIDO
A2: abre bocas Umbrella | E2: 0 | F2: 0 | G2: Pluss Dent GAB VEL | H2: 0 | I2: 0 | K2: =9288*1.19 -> 11052.72 | L2: 15000 | O2: =(L2/K2)-1 -> 0.357132 | P2: =K2*F2 -> 0
A3: Abreboca manual gancho DOBLE EXTREMO NEGRO | E3: 0 | F3: 0 | G3: IMPORTADA | I3: 8 | K3: 8746 | L3: 30000 | M3: 19 | O3: =(L3/K3)-1 -> 2.4301395 | P3: =K3*F3 -> 0
A4: Abreboca manual gancho DOBLE EXTREMO TRANSPARENTE | E4: 0 | F4: 0 | G4: IMPORTADA | I4: 50 | K4: =1962*2 -> 3924 | L4: 30000 | O4: =(L4/K4)-1 -> 6.6452599 | P4: =K4*F4 -> 0
A5: Abreboca manual gancho PEQUEÑO | E5: 0 | F5: 0 | G5: IMPORTADA | I5: 100 | K5: 1712 | L5: 10000 | O5: =(L5/K5)-1 -> 4.8411215 | P5: =K5*F5 -> 0
A6: Abreboca AZUL Y ROJO AMARILLO | E6: 0 | F6: 0 | G6: ELVER LOZANO BOGOTA | I6: rojo 1 azul 1 | K6: 4500 | L6: 12000 | O6: =(L6/K6)-1 -> 1.6666667 | P6: =K6*F6 -> 0
A7: abreboca Con retractor adulto | E7: 0 | F7: 0 | G7: UPEGUI | I7: BLANCO 43 NEGRO 10 | K7: 16900 | L7: 24000 | O7: =(L7/K7)-1 -> 0.42011834 | P7: =K7*F7 -> 0
A8: abreboca Con retractor PEDIATRICO | E8: 0 | F8: 0 | G8: UPEGUI | I8: 20 | K8: 16900 | L8: 24000 | O8: =(L8/K8)-1 -> 0.42011834 | P8: =K8*F8 -> 0
A9: Abreboca manual gancho GRANDE | E9: 0 | F9: 0 | G9: IMPORTADA | I9: 50 | K9: 1426.9789 | L9: 10000 | O9: =(L9/K9)-1 -> 6.0078119 | P9: =K9*F9 -> 0
A10: Abreboca sencillo adulto | B10: OXXI $ 11067 NISSI $7556 | E10: 0 | F10: 0 | G10: OXXI NISSI | I10: =8+16*5 -> 88 | K10: =9300*1.19/5 -> 2213.4 | L10: 8000 | O10: =(L10/K10)-1 -> 2.614349 | P10: =K10*F10 -> 0
A11: Abreboca sencillo niño | B11: OXXI $ 11067 NISSI $7557 | E11: 0 | F11: 0 | G11: OXXI NISSI | I11: 26 | K11: =9300*1.19/5 -> 2213.4 | L11: 8000 | O11: =(L11/K11)-1 -> 2.614349 | P11: =K11*F11 -> 0
A12: abreboca sin retractor | E12: 0 | F12: 0 | G12: UPEGUI | I12: 10 | K12: 16900 | L12: 24000 | O12: =(L12/K12)-1 -> 0.42011834 | P12: =K12*F12 -> 0
A13: abrebocas aclaramiento tipo optragate | E13: 0 | F13: 0 | G13: IMPORTADA | I13: 58 | K13: 4602 | L13: 12000 | O13: =(L13/K13)-1 -> 1.6075619 | P13: =K13*F13 -> 0
A14: Accufilm Papel de articular aqua film x 280 tiras | E14: 0 | F14: 0 | G14: La muela miguel | I14: 1 | K14: =65000/200 -> 325 | L14: 800 | O14: =(L14/K14)-1 -> 1.4615385 | P14: =K14*F14 -> 0
A15: Accufilm Papel de articular CIRENE aqua film x 280 tiras | E15: 0 | F15: 0 | G15: La muela miguel | K15: 65000 | L15: 105000 | N15: 90000 | O15: =(L15/K15)-1 -> 0.61538462 | P15: =K15*F15 -> 0
A16: Aceite 3 en 1 | E16: 0 | G16: CENTRO HOYOSTOOL | K16: =3200*1.19 -> 3808 | L16: 6000 | O16: =(L16/K16)-1 -> 0.57563025 | P16: =K16*F16 -> 0
A17: aceite lubricante - pieza de mano Dental handpiece 300ml | E17: 0 | F17: 0 | G17: DTM | K17: 28000 | L17: 48000 | N17: 38000 | O17: =(L17/K17)-1 -> 0.71428571
A18: aceite lubricante - pieza de mano Dental handpiece 550ml | E18: 0 | F18: 0 | G18: DTM | K18: 35000 | L18: 54000 | N18: 44000 | O18: =(L18/K18)-1 -> 0.54285714
A19: aceite lubricante - pieza de mano PANASPRAY PLUS NSK 480ML | B19: NSK | E19: 0 | F19: 0 | G19: LA MUELA | I19: 10 | J19: 45717 | K19: =121849*1.19 -> 145000.31 | L19: 178000 | N19: 168000 | O19: =(L19/K19)-1 -> 0.22758358 | P19: =K19*F19 -> 0
A20: aceite lubricante - pieza de mano WYH 400ML | B20: euro $96250 | G20: MASDENTAL EURODENT | I20: 0 | K20: 116000 | L20: 145000 | N20: 120000 | O20: =(L20/K20)-1 -> 0.25 | P20: =K20*F20 -> 0
A21: Aceite lubricante Bendechk 300ml | E21: 0 | F21: 0 | G21: makrodent DTM | K21: 35000 | L21: 48000 | O21: =(L21/K21)-1 -> 0.37142857 | P21: =K21*F21 -> 0
A22: aceite lubricante de piezas digixpray 240ml | E22: 0 | F22: 0 | G22: muela | K22: 24850 | L22: 48000 | M22: iva | N22: 34000
A23: Aceite lubricante en Spray 200 ml- KAVO | C23: AGOTADO | E23: 0 | F23: 0 | G23: Pluss Dent GAB VEL | H23: 0 | I23: 0 | K23: 49504 | L23: 65000 | O23: =(L23/K23)-1 -> 0.31302521 | P23: =K23*F23 -> 0
A24: aceite lubricante pequeño - pieza de mano 50 ml | E24: 0 | G24: RAMON | K24: 7400 | L24: 12000 | O24: =(L24/K24)-1 -> 0.62162162 | P24: =K24*F24 -> 0
A25: Aceite lubricante Quiruspray 200 cc - pieza de mano | B25: ramon $29.500 aquiles $24.871 | E25: 0 | G25: RAMON AQUILES | K25: =24789.92*1.19 -> 29500.005 | L25: 39000 | O25: =(L25/K25)-1 -> 0.32203368 | P25: =K25*F25 -> 0
A26: Aceite lubricante Universal en Spray 250 ml- Adensys | E26: 0 | F26: 0 | G26: Pluss Dent GAB VEL | H26: 0 | I26: 10 | J26: 46174 | K26: =50500*1.19 -> 60095 | L26: 76000 | N26: 65000 | O26: =(L26/K26)-1 -> 0.26466428 | P26: =K26*F27 -> 0
A27: Aceite LUBRICANTE X200 ML Maquira | E27: 0 | F27: 0 | G27: SOCCIDENTALES | I27: 0 | J27: 46174 | K27: =26000*1.19 -> 30940 | L27: 55000 | O27: =(L27/K27)-1 -> 0.77763413 | P27: =K27*#REF! -> #REF!
A28: Aceite super lubry 50ml | E28: 0 | F28: 0 | G28: AQUILES | I28: 0 | J28: 46174 | K28: 7500 | L28: 12000 | O28: =(L28/K28)-1 -> 0.6 | P28: =K28*F28 -> 0
A29: acetato lamina rosada 0.6 | E29: 0 | G29: RAMON | K29: 1800 | L29: 3500 | O29: =(L29/K29)-1 -> 0.94444444 | P29: =K29*F29 -> 0
A30: acetato rigido ACE | E30: 0 | G30: RAMON | K30: 6400 | L30: 9000 | O30: =(L30/K30)-1 -> 0.40625 | P30: =K30*F30 -> 0
A31: acido clorhidrico removedor de manchas opalustre FGM whiteness RM 6% | B31: antioq $95200 soccid $ 80,206 plus $79968 | E31: 0 | F31: 0 | G31: FGM soccident | I31: 0 | J31: 46082 | K31: =100000*0.8*1.19 -> 95200 | L31: 145000 | O31: =(L31/K31)-1 -> 0.52310924 | P31: =K31*F31 -> 0
A32: Acido desmineralizante 2.5 coltene | B32: ACIDO | E32: 0 | F32: 0 | G32: Ultradental | I32: 0 | K32: 10868 | L32: 18000 | O32: =(L32/K32)-1 -> 0.6562385 | P32: =K32*F32 -> 0
A33: acido desmineralizante 2.5 Densell 12g 35% | B33: ACIDO | E33: 0 | F33: 0 | G33: La muela - ramon | J33: 46478 | K33: 12000 | L33: 20000 | M33: exc | N33: 18000 | O33: =(L33/K33)-1 -> 0.66666667 | P33: =K33*F33 -> 0
A34: Acido desmineralizante 35% ultradent 1.2ml | B34: ACIDO | E34: 2 | F34: 0 | G34: Gabriel Vel pluss | H34: 2 | I34: 3 | K34: 13272 | L34: 22000 | O34: =(L34/K34)-1 -> 0.65762508 | P34: =K34*F34 -> 0
A35: acido desmineralizante 37% fosforico MAQUIRA 2.5 | B35: ACIDO | C35: PRECIO MAYO 20 | D35: =(6500*1.19)/3 -> 2578.3333 | E35: 0 | F35: 0 | G35: RAMON CLAUDIA SOCCIDENTALES | J35: 45962 | K35: =(11654*1.19)/3 -> 4622.7533 | L35: 13000 | M35: EXC | O35: =(L35/K35)-1 -> 1.8121769 | P35: =K35*F35 -> 0
A36: acido desmineralizante angelus 3 grs | B36: ACIDO | E36: 0 | F36: 0 | G36: CLAUDIA | I36: 0 | K36: 2000 | L36: 10000 | O36: =(L36/K36)-1 -> 4 | P36: =K36*F36 -> 0
A37: Acido desmineralizante FGM condac 12.5 ML | B37: ACIDO promo antoq $24375 SOCCIDEN 20825 plus20000 | E37: 0 | F37: 0 | G37: FGM soccident | I37: 0 | J37: 45992 | K37: =32500*0.8 -> 26000 | L37: 35000 | M37: exc | O37: =(L37/K37)-1 -> 0.34615385 | P37: =K37*F37 -> 0
A38: Acido Desmineralizante proquident 10ML jumbo | B38: ACIDO | G38: PROQUIDENT | I38: 2 | J38: 46844 | K38: 14173 | L38: 24000 | O38: =(L38/K38)-1 -> 0.69336062 | P38: =K38*#REF! -> #REF!
A39: Acido Desmineralizante Select H V ETCH 5ML Bisco | B39: promo $48.450 mayo/25 | G39: JULVIDENT bisco | I39: 11 | J39: 46447 | K39: 54000 | L39: 68000 | M39: EXC | O39: =(L39/K39)-1 -> 0.25925926 | P39: =K39*F39 -> 0
A40: Acido desmineralizante SUPER ETCH SDI 12 gm | B40: ACIDO | E40: 0 | F40: 0 | G40: ABRAHAM | I40: 6 | J40: 46296 | K40: 33800 | L40: 42500 | M40: exc | O40: =(L40/K40)-1 -> 0.25739645 | P40: =K40*F40 -> 0
...

Sheet AGOTADOS SUR
A1: fecha | B1: LO QUE FALTA | C1: observaciones | F1: NOTA NORTE
A2: 45716 | B2: ENDO FROST | C2: PEDIR | D2: norte no hay | E2: PEDIR | F2: pedir
A3: 45783 | B3: cepillos interdentales granel y viajero | C3: norte | D3: agotado norte | E3: PEDIR | F3: ya mandamos junio 28
A4: 45787 | B4: sellantes maquira | C4: DE CUALES ? | D4: ya mande | F4: pedir
A5: 45800 | B5: 6 GUANTES NEGRO NITRILO TALLA S | C5: MIENTRAS PEDIMOS | F5: pedir
A6: 45805 | B6: acido sdi | C6: agotado | F6: ya mandamos junio 28
A7: 45821 | B7: Pesada Zhermack | C7: norte | D7: de las 2 presentciones | F7: ya mandamos junio 28
A8: 45821 | B8: Pesada Panasil | C8: norte | D8: 400ml | F8: ya mandamos junio 28
A9: 45821 | B9: PRIMMA ART | C9: norte | F9: ya mandamos junio 28
A10: 45821 | B10: ENEBRADORES | C10: norte | F10: ya mandamos junio 28
A11: 45827 | B11: felpa peluche | C11: norte | D11: agotado norte | F11: ya se mando pedir
A12: 45827 | B12: felpa pelo de cabra beige HP | C12: norte | D12: agotado norte | F12: ya se mando pedir
A13: 45827 | B13: septanes 1/100 | C13: norte | D13: agotado norte | E13: donde abraham ya llego con bueba fecha | F13: pedir
A14: 45833 | B14: piedra pomex lib | C14: norte | D14: agotado norte | F14: pedir
A15: 45834 | B15: alginato orthopint | C15: norte | D15: agotado | F15: pedir
A16: 45839 | B16: POSTES AMARILLOS | C16: norte
A17: 45839 | B17: ORTHOPRINT | C17: norte

Sheet COPIA INSTRUMENTAL SUR 
A1: Perico | B1: nelly | C1: FERCHO | D1: CRIST | E1: PEDIDO NORTE | H1: PERICO dcto 12% + iva | I1: NELLY dcto 15% + iva | J1: CRISTIAN | K1: AQUILES FERCHO | L1: a quien pedir) | N1: PRECIO DEL PEDIDO | O1: MALETERO | P1: costo | Q1: VR TOTAL | R1: PRECIO DE VENTA | S1: %
E2: 0 | F2: ABREBOCA MOLT ADULTO | H2: =24000*0.88*1.19 -> 25132.8 | L2: PERICO | M2: =24000*0.88*1.19 -> 25132.8 | N2: =E2*J2 -> 0 | P2: =H2*O2 -> 0 | Q2: =R2*O2 -> 0 | R2: 45000 | S2: =(R2/H2)-1 -> 0.79048892
E3: 0 | F3: ABREBOCA MOLT PEDIATRICO | H3: =24000*0.88*1.19 -> 25132.8 | L3: PERICO | M3: =24000*0.88*1.19 -> 25132.8 | N3: =E3*J3 -> 0 | P3: =H3*O3 -> 0 | Q3: =R3*O3 -> 0 | R3: 45000 | S3: =(R3/H3)-1 -> 0.79048892
E4: 0 | F4: ALICATE 2 PICOS # 139 | H4: =18700*0.88*1.19 -> 19582.64 | I4: =+25227*0.85*1.19 -> 25517.11 | K4: =18000*0.85*1.19 -> 18207 | L4: AQUILES | M4: =18000*0.85*1.19 -> 18207 | N4: =K4*E4 -> 0 | O4: 30000 | P4: =C4*K4 -> 0 | Q4: =R4*O4 -> 1020000000 | R4: 34000 | S4: =(R4/H4)-1 -> 0.73623168
E5: 0 | F5: ALICATE 3 PICOS # 200 | H5: =18700*0.88*1.19 -> 19582.64 | I5: =+25227*0.85*1.19 -> 25517.11 | K5: =18000*0.85*1.19 -> 18207 | L5: AQUILES | M5: =18000*0.85*1.19 -> 18207 | N5: =K5*E5 -> 0 | P5: =C5*K5 -> 0 | Q5: =R5*O5 -> 0 | R5: 34000 | S5: =(R5/H5)-1 -> 0.73623168
E6: 10 | F6: ALICATE PINZA QUITA BANDAS # 34 | G6: PRECIO PERICO $20980 | H6: =19000*0.88*1.19 -> 19896.8 | I6: =25227*0.85*1.19 -> 25517.11 | L6: PERICO | M6: =19000*0.88*1.19 -> 19896.8 | N6: =E6*H6 -> 198968 | P6: =H6*O6 -> 0 | Q6: =R6*O6 -> 0 | R6: 34000 | S6: =(R6/H6)-1 -> 0.7088175
E7: 0 | F7: Aplicador de ligaduras llaves y cadenetas Morelly | R7: 28000 | S7: =(R7/H7)-1 -> #DIV/0!
E8: 5 | F8: APLICADOR DICAL | H8: =3700*0.88*1.19 -> 3874.64 | I8: =3507*0.85*1.19 -> 3547.3305 | K8: =3800*0.85*1.19 -> 3843.7 | L8: AQUILES | M8: =3800*0.85*1.19 -> 3843.7 | N8: =K8*E8 -> 19218.5 | P8: =C8*K8 -> 0 | Q8: =R8*O8 -> 0 | R8: 7000 | S8: =(R8/H8)-1 -> 0.80661945
E9: 0 | F9: arco de Young De ADULTO OJO GRANDE instrumental | H9: =7400*0.88*1.19 -> 7749.28 | I9: N / V | K9: =5000*0.85*1.19 -> 5057.5 | L9: AQUILES | M9: =5000*0.85*1.19 -> 5057.5 | N9: =K9*E9 -> 0 | P9: =C9*K9 -> 0 | Q9: =R9*O9 -> 0 | R9: 14000 | S9: =(R9/H9)-1 -> 0.80661945
E10: 0 | F10: arco de Young pediatrico Pño instrumental | H10: =7400*0.88*1.19 -> 7749.28 | I10: N / V | K10: =5000*0.85*1.19 -> 5057.5 | L10: AQUILES | M10: =5000*0.85*1.19 -> 5057.5 | N10: =K10*E10 -> 0 | P10: =C10*K10 -> 0 | Q10: =R10*O10 -> 0 | R10: 14000 | S10: =(R10/H10)-1 -> 0.80661945
E11: 0 | F11: Asentador de bandas 300 X instrumental (PARECE ELEVADOR) bandpusher | H11: =9000*0.88*1.19 -> 9424.8 | I11: =13740*0.85*1.19 -> 13898.01 | J11: 5000 | L11: CRISTIAN | M11: 5000 | N11: =E11*H11 -> 0 | P11: =O11*H11 -> 0 | Q11: =R11*O11 -> 0 | R11: 30000 | S11: =(R11/H11)-1 -> 2.1830914
E12: 10 | F12: Asentador de bandas color | H12: =5500*0.88*1.19 -> 5759.6 | L12: PERICO | M12: =5500*0.88*1.19 -> 5759.6 | N12: =E12*J12 -> 0 | P12: =H12*O12 -> 0 | Q12: =R12*O12 -> 0 | R12: 24000 | S12: =(R12/H12)-1 -> 3.166956
E13: 0 | F13: Asentador de Bandas MORELI | R13: 32000
E14: 10 | F14: BISTURI DE KIRKLAN INSTRUMENTAL | H14: =5000*0.88*1.19 -> 5236 | L14: PERICO | M14: =5000*0.88*1.19 -> 5236 | N14: =E14*H14 -> 52360 | O14: 8000 | P14: =O14*H14 -> 41888000 | Q14: =R14*O14 -> 80000000 | R14: 10000 | S14: =(R14/H14)-1 -> 0.90985485
E15: 6 | F15: BISTURI DE ORBAN INSTRUMENTAL | H15: =4800*0.88*1.19 -> 5026.56 | I15: =7139*0.85*1.19 -> 7221.0985 | L15: PERICO | M15: =4800*0.88*1.19 -> 5026.56 | N15: =E15*H15 -> 30159.36 | O15: 8000 | P15: =H15*O15 -> 40212480 | Q15: =R15*O15 -> 80000000 | R15: 10000 | S15: =(R15/H15)-1 -> 0.98943214
E16: 0 | F16: Bruñidor 21 B | H16: =5000*0.88*1.19 -> 5236 | K16: =5000*0.85*1.19 -> 5057.5 | L16: AQUILES | M16: =5000*0.85*1.19 -> 5057.5 | N16: =E16*J16 -> 0 | P16: =C16*K16 -> 0 | Q16: =R16*O16 -> 0 | R16: 8000 | S16: =(R16/H16)-1 -> 0.52788388
E17: 0 | F17: Bruñidor de Bola y orqueta | H17: =5000*0.88*1.19 -> 5236 | K17: =5000*0.85*1.19 -> 5057.5 | L17: AQUILES | M17: =5000*0.85*1.19 -> 5057.5 | N17: =E17*J17 -> 0 | P17: =C17*K17 -> 0 | Q17: =R17*O17 -> 0 | R17: 8000 | S17: =(R17/H17)-1 -> 0.52788388
D18: 20 | F18: CADENA PORTA BABERO | J18: 2500 | L18: CRISTIAN | M18: 2500 | P18: =K18*O18 -> 0 | Q18: =R18*O18 -> 0 | R18: 6000 | S18: =(R18/J18)-1 -> 1.4
E19: 0 | F19: Calibrador de cera instrumental | G19: precio crstian $10000 | H19: =10000*1.19*0.88 -> 10472 | I19: =16786*1.19*0.85 -> 16979.039 | J19: 8000 | K19: =10000*0.85*1.19 -> 10115 | L19: CRISTIAN | M19: 8000 | N19: =E19*H19 -> 0 | P19: =C19*K19 -> 0 | Q19: =R19*O19 -> 0 | R19: 24000 | S19: =(R19/H19)-1 -> 1.2918258
E20: 0 | F20: calibrador de metal instrumental | H20: =11000*1.19*0.88 -> 11519.2 | I20: =16786*0.85*1.19 -> 16979.039 | J20: 8000 | K20: =10000*0.85*1.19 -> 10115 | L20: CRISTIAN | M20: 8000 | N20: =E20*H20 -> 0 | P20: =C20*K20 -> 0 | Q20: =R20*O20 -> 0 | R20: 24000 | S20: =(R20/H20)-1 -> 1.083478
E21: 0 | F21: calibrador pie de rey | L21: CRISTIAN | R21: 24000
E22: 0 | F22: Castro Viejo instrumental (OJO PINZA QUE TIENE GANCHO EN EL MEDIO) | H22: =24900*0.88*1.19 -> 26075.28 | I22: =30945*0.85*1.19 -> 31300.868 | L22: CRISTIAN | M22: 26071 | N22: =E22*J22 -> 0 | O22: 35000 | P22: =K22*O22 -> 0 | Q22: =R22*O22 -> 1470000000 | R22: 42000 | S22: =(R22/H22)-1 -> 0.61072096
E23: 0 | F23: Castro Viejo instrumental tijera | H23: =18000*0.88*1.19 -> 18849.6 | I23: 25601 | J23: 19000 | L23: CRISTIAN | M23: 19000 | N23: =E23*J23 -> 0 | O23: 35000 | P23: =K23*O23 -> 0 | Q23: =R23*O23 -> 1470000000 | R23: 42000 | S23: =(R23/H23)-1 -> 1.228164
E24: 0 | F24: CK 4 | H24: =5000*0.88*1.19 -> 5236 | I24: =6267*0.85*1.19 -> 6339.0705 | K24: =5000*0.85*1.19 -> 5057.5 | L24: AQUILES | M24: =5000*0.85*1.19 -> 5057.5 | N24: =K24*E24 -> 0 | O24: 8000 | P24: =C24*K24 -> 0 | Q24: =R24*O24 -> 80000000 | R24: 10000 | S24: =(R24/H24)-1 -> 0.90985485
E25: 0 | F25: CK 6 | H25: =5000*0.88*1.19 -> 5236 | J25: 3000 | K25: =5000*0.85*1.19 -> 5057.5 | L25: CRISTIAN | M25: 3000 | N25: =E25*J25 -> 0 | P25: =C25*K25 -> 0 | Q25: =R25*O25 -> 0 | R25: 10000 | S25: =(R25/H25)-1 -> 0.90985485
E26: 0 | F26: CONDENSADOR DE AMALGAMA | H26: =4800*0.88*1.19 -> 5026.56 | L26: PERICO | M26: =5000*0.88*1.19 -> 5236 | N26: =E26*J26 -> 0 | P26: =O26*H26 -> 0 | Q26: =R26*O26 -> 0 | R26: 10000 | S26: =(R26/H26)-1 -> 0.98943214
E27: 0 | F27: Corte de Ligadura ortodoncia | H27: =22000*0.88*1.19 -> 23038.4 | I27: =25227*0.85*1.19 -> 25517.11 | L27: PERICO | M27: =22000*0.88*1.19 -> 23038.4 | N27: =E27*J27 -> 0 | O27: 35000 | R27: 40000 | S27: =(R27/H27)-1 -> 0.73623168
E28: 0 | F28: Corte de Ligadura ortodoncia angelus | R28: 80000 | S28: =(R28/H28)-1 -> #DIV/0!
E29: 5 | F29: Corte Distal ORTODONCIA | H29: =29700*0.88*1.19 -> 31101.84 | L29: PERICO | M29: =29700*0.88*1.19 -> 31101.84 | N29: =E29*J29 -> 0 | O29: 42000 | R29: 48000 | S29: =(R29/H29)-1 -> 0.54331705
E30: 10 | F30: CUBETAS PARA IMPRESIÓN ADULTOS | H30: =58500*0.88*1.19 -> 61261.2 | I30: 64867 | K30: =58000*0.85*1.19 -> 58667 | L30: AQUILES | M30: =58000*0.85*1.19 -> 58667 | N30: =K30*E30 -> 586670 | O30: 74000 | P30: =C30*K30 -> 0 | R30: 95000 | S30: =(R30/H30)-1 -> 0.55073684
E31: 0 | F31: CUBETAS PARA IMPRESIÓN pediatrico | H31: =58500*0.88*1.19 -> 61261.2 | I31: 64867 | K31: =58000*0.85*1.19 -> 58667 | L31: AQUILES | M31: =58000*0.85*1.19 -> 58667 | N31: =K31*E31 -> 0 | P31: =C31*K31 -> 0 | Q31: =R31*O31 -> 0 | R31: 95000 | S31: =(R31/H31)-1 -> 0.55073684
E32: 20 | F32: Cucharilla #17 Puppies | H32: =4800*0.88*1.19 -> 5026.56 | L32: PERICO | M32: =4800*0.88*1.19 -> 5026.56 | N32: =E32*J32 -> 0 | R32: 9000 | S32: =(R32/H32)-1 -> 0.79048892
E33: 0 | F33: Cucharilla basico instrumental | G33: BASICO | H33: =4800*0.88*1.19 -> 5026.56 | I33: =5494*0.85*1.19 -> 5557.181 | K33: =5000*0.85*1.19 -> 5057.5 | L33: AQUILES | M33: =5000*0.85*1.19 -> 5057.5 | N33: =K33*E33 -> 0 | P33: =C33*K33 -> 0 | Q33: =R33*O33 -> 0 | R33: 9000 | S33: =(R33/H33)-1 -> 0.79048892
E34: 0 | F34: CUCHILLO PROTESIS GRANDE | H34: =7000*0.88*1.19 -> 7330.4 | I34: 3724 | J34: 4000 | K34: =6500*0.85*1.19 -> 6574.75 | L34: CRISTIAN | M34: 4000 | N34: =E34*J34 -> 0 | O34: 10000 | P34: =C34*K34 -> 0 | Q34: =R34*O34 -> 130000000 | R34: 13000 | S34: =(R34/H34)-1 -> 0.77343665
E35: 0 | F35: Cureta 11/12 instrumental Mc Call | G35: precio cristian $4000 | H35: =5000*1.19*0.88 -> 5236 | I35: =6043*0.85*1.19 -> 6112.4945 | L35: PERICO | M35: =5000*1.19*0.88 -> 5236 | N35: =E35*H35 -> 0 | P35: =H35*O35 -> 0 | Q35: =R35*O35 -> 0 | R35: 9000 | S35: =(R35/H35)-1 -> 0.71886937
E36: 5 | F36: Cureta 13/14 instrumental Mc Call | H36: =5000*1.19*0.88 -> 5236 | I36: =6043*0.85*1.19 -> 6112.4945 | K36: =5000*0.85*1.19 -> 5057.5 | L36: AQUILES | M36: =5000*0.85*1.19 -> 5057.5 | N36: =K36*E36 -> 25287.5 | P36: =C36*K36 -> 0 | Q36: =R36*O36 -> 0 | R36: 9000 | S36: =(R36/H36)-1 -> 0.71886937
E37: 0 | F37: Cureta 15/16 instrumental Mc Call | H37: =5000*1.19*0.88 -> 5236 | I37: =6043*0.85*1.19 -> 6112.4945 | L37: PERICO | M37: =5000*1.19*0.88 -> 5236 | N37: =E37*H37 -> 0 | P37: =K37*O37 -> 0 | Q37: =R37*O37 -> 0 | R37: 9000 | S37: =(R37/H37)-1 -> 0.71886937
E38: 0 | F38: Cureta 17/18 instrumental Mc Call | H38: =5000*1.19*0.88 -> 5236 | I38: =6043*0.85*1.19 -> 6112.4945 | K38: =5000*0.85*1.19 -> 5057.5 | L38: AQUILES | M38: =5000*0.85*1.19 -> 5057.5 | N38: =K38*E38 -> 0 | P38: =C38*K38 -> 0 | Q38: =R38*O38 -> 0 | R38: 9000 | S38: =(R38/H38)-1 -> 0.71886937
D39: 12 | E39: 1 | F39: cureta de Lucas #85 | G39: precio cristian 5600 | H39: =4800*1.19*0.88 -> 5026.56 | I39: =6043*0.85*1.19 -> 6112.4945 | J39: 3300 | K39: =5000*0.85*1.19 -> 5057.5 | L39: CRISTIAN | M39: 3300 | N39: =E39*J39 -> 3300 | P39: =C39*K39 -> 0 | Q39: =R39*O39 -> 0 | R39: 9000 | S39: =(R39/H39)-1 -> 0.79048892
D40: 4 | F40: CURETA Gracey 1/2 Instrumental | H40: =5000*1.19*0.88 -> 5236 | I40: =6043*0.85*1.19 -> 6112.4945 | J40: 3700 | L40: CRISTIAN | M40: 3700 | N40: =E40*J40 -> 0 | P40: =K40*O40 -> 0 | Q40: =R40*O40 -> 0 | R40: 9000 | S40: =(R40/H40)-1 -> 0.71886937
...

Sheet TEMPO NORTE PEDIDO EUFAR
B2: pedi junio 28 | C2: referencias | F2: PEDIDO SUR | G2: PEDIDO NORTE | I2: INVENT SUR mar 21 | J2: INVENT NTE | K2: FECHA VCMTO | L2: PRECIO COMPRA | M2: precio venta
B3: acido fluorhidrico 9.6% Jeringa 2 g Eufar | C3: Aquiles $32000 ramon $32000 EUFAR $29354 | G3: 5 | H3: AQUILES RAMON GABRIEL VELASQUEZ Eufar | J3: 3 | L3: =24667*1.19 -> 29353.73 | M3: 45000 | N3: =G3*L3 -> 146768.65
B4: ALVOFAR eufar | G4: 0 | H4: RAMON-eufar | J4: 0 | K4: muy costoso no pedi | L4: 48744 | M4: 62000 | N4: =G4*L4 -> 0
B5: CALCIFAR - P JERINGA 2ML Hidroxido de calcio en pasta | G5: 0 | H5: eufar | J5: 0 | L5: 25935 | M5: 36000
B6: DENTOFAR 5 ML | C6: aquiles $22325 EUFAR 21385 | G6: 0 | H6: EUFAR proquident AQUILES | J6: 3 | L6: 21385 | M6: 28000
B7: desinfectantes ALCOHOL 80% x 240 ml eucida clasicc | G7: 10 | H7: eufar | J7: 11 | L7: 12285 | M7: 17000 | N7: =G7*L7 -> 122850
B8: EDTA 120 ml eufar | C8: aquiles $40000 eufar $36985 | G8: 0 | H8: Gabriel Velasquez - aquiles Eufar | J8: 6 | L8: 36985 | M8: 58000
B9: Eucida Advanced Solución desinfectante de dispositivos médicos superficie 240ML | G9: 0 | H9: RAMON EUFAR | J9: 13 | K9: 46569 | L9: 12285 | M9: 18000
B10: EUGENOL EUFAR 15ml | G10: 0 | H10: eufar | J10: 15 | L10: 10985 | M10: 16000
B11: fluofar chicle x 240 ml | C11: EUFAR 12299 AQUILES 13566 | G11: 0 | H11: AQUILES EUFAR | J11: 4 | L11: =10335*1.19 -> 12298.65 | M11: 18000
B12: fluor fluofar neutro 240 ML | C12: AQULIES $22848 | G12: 0 | H12: ramon-aquiles - eufar - proquident | J12: 1 | L12: =21385*1.19 -> 25448.15 | M12: 35000
B13: fluor neutro 50 ML | C13: EUFAR 11525 proquident 8935 | G13: 5 | H13: ramon-aquiles PROQUIDENT EUFAR | J13: 4 | K13: 1/10/2026 12-2026 4-2028 | L13: =9685*1.19 -> 11525.15 | M13: 15000 | N13: =G13*L13 -> 57625.75
B14: GOTAS REVELADORAS DITONOS | C14: AQUILES $11,400 | G14: 0 | H14: EUFAR | J14: 0 | L14: =10367*1.19 -> 12336.73 | M14: 15000
B15: hemofar sulfato ferrico EUFAR | G15: 0 | H15: Gabriel Velasquez Eufar | J15: 3 | K15: 46447 | L15: =10985 -> 10985 | M15: 18000
B16: HIDROXIDO DE CALCIO X 10 gm prodont | D16: actualizar 4297 | G16: 0 | H16: RAMON-PROQUIDENT-PRODONT Aquiles Eufar | J16: 10 | K16: 46508 | L16: 7961 | M16: 8000
B17: HIDROXIDO DE CALCIO X 7gm proquident | G17: 0 | H17: RAMON-PROQUIDENT-PRODONT Aquiles Eufar | J17: 10 | L17: 5114 | M17: 8000
B18: JABON DE MANOS 500ML bonfar | G18: 5 | H18: EUFAR | J18: 12 | K18: 46539 | L18: =12935*1.19 -> 15392.65 | M18: 18000 | N18: =G18*L18 -> 76963.25
B19: MOMIFAR 7ML MOMIFICANTE PULPAR X 7 ML EUFAR | G19: 10 | H19: RAMON PRODONT EUFAR | J19: 6 | K19: 46388 | L19: 9620 | M19: 13000 | N19: =G19*L19 -> 96200
B20: MOMIFICANTE PULPAR X 7 ML MOMICIDE | G20: 0 | H20: RAMON PRODONT EUFAR | J20: 0 | K20: 46388 | L20: 9243 | M20: 12000
B21: Pasta Profilactica EUFAR TUBO colapsible Detarfar 50gm | C21: =9685*1.19 -> 11525.15 | G21: 10 | H21: EUFAR | J21: 3 | K21: 46844 | L21: =9685*1.19 -> 11525.15 | M21: 14000 | N21: =G21*L21 -> 115251.5
B22: Pasta Profilactica EUFAR TUBO DETARFAR GRANDE 345gm | G22: 1 | H22: EUFAR | J22: 0 | K22: 46843 | L22: =25945*1.19 -> 30874.55 | M22: 44000 | N22: =G22*L22 -> 30874.55
B23: Retracfar Cloruro de aluminio 7ml | G23: 1 | H23: ramon EUFAR PRODONT AQUILES | J23: 0 | L23: 9685 | M23: 15000 | N23: =G23*L23 -> 9685

Sheet TEMPO NORTE PEDIDO PRODONT
B2: pedi junio 28 | C2: referencias | F2: PEDIDO SUR | G2: PEDIDO NORTE | I2: INVENT SUR mar 21 | J2: INVENT NTE
B3: ACIDO FLUORHIDRICO 3ML (JERINGA) prodont | G3: 5 | H3: PRODONT | J3: 4
B4: ACIDO FLUORHIDRICO 7ML (GOTERO) prodont | G4: 0 | H4: PRODONT | J4: 9
B5: Cemento C-Gross | C5: NO PEDIR | G5: 0 | H5: PRODONT | J5: 0
B6: EUGENOL X 7 ML prodont | C6: PRODONT | G6: 10 | H6: PRODONT | J6: 12
B7: GLUTARALDEHIDO BACTIXIDE PRODONT x 500 cc (YA MEZCLADA) | C7: MEDIO LITRO | D7: BORRAR | G7: 0 | H7: PRODONT | J7: 0
B8: Hemostatico Cloruro de aluminio x 7ml hemodent prodont | G8: 5 | H8: RAMON PRODONT | J8: 15
B9: HIDROXIDO DE CALCIO X 10 gm prodont | D9: actualizar 4297 | G9: 0 | H9: RAMON-PROQUIDENT-PRODONT Aquiles Eufar | J9: 10
B10: HIDROXIDO DE CALCIO X 7gm proquident | G10: 0 | H10: RAMON-PROQUIDENT-PRODONT Aquiles Eufar | J10: 10
B11: HIPOCLORITO AL 1% X 120 ML | G11: 1 | H11: RAMON PRODONT | J11: 1
B12: HIPOCLORITO AL 5 % X 120 ML | C12: PROQUID $3370 // PRODONT $5095 | G12: 30 | H12: PRODONT | J12: 15
B13: Jabon Enzimatico x 120 cc prodont | C13: PROQUIDENT $5280 PRODONT $6993 GARHOX $7735 | G13: 10 | H13: PRODONT | J13: 24
B14: Jabon multienzimatico bactixide 500 ml | D14: BORRAR | G14: 0 | H14: PRODONT | J14: 0
B15: LECHADA DE CALCIO SIDCAL X 500 ML prodont | G15: 0 | H15: PRODONT | J15: 5
B16: MOMIFAR 7ML MOMIFICANTE PULPAR X 7 ML EUFAR | G16: 0 | H16: RAMON PRODONT EUFAR | J16: 30
B17: MOMIFICANTE PULPAR X 7 ML MOMICIDE | G17: 0 | H17: RAMON PRODONT EUFAR
B18: Oxido de zinc 10g | G18: 0 | H18: RAMON PROQUIDENT PRODONT | J18: 10
B19: Pasta Profilactica (tutifruti - fresa) TUBO colapsible prodont | C19: prodont 10144 | G19: 0 | H19: PRODONT | J19: 20
B20: perborato de sodio | G20: 0 | H20: PRODONT | J20: 0
B21: Retracfar Cloruro de aluminio 7ml | G21: 2 | H21: ramon EUFAR PRODONT AQUILES | J21: 0
B22: Topsensy desensibilizante dental 5 ml dentofar | G22: 0 | H22: Prodont | J22: 2
B23: Xilol prodont 15ML | G23: 10 | H23: RAMON PROQUIDENT PRODONT | J23: 7

Sheet TEMPO PEDIDO GUANTES NORTE
B2: NORTE | C2: LATEX | D2: NITRILO | K2: TOTAL NORTE Y SUR | L2: LATEX | M2: NITRILO
D3: AZUL | E3: NEGRO | F3: MORADO | G3: ROSADO | M3: AZUL | N3: NEGRO | O3: MORADO | P3: ROSADO
B4: XS | C4: 46 | D4: 39 | E4: 22 | F4: 10 | G4: 10 | K4: XS | L4: =C4+C10 -> 79 | M4: =D4+D10 -> 69 | N4: =E4+E10 -> 33 | O4: =F4+F10 -> 18 | P4: =G4+G10 -> 39
B5: S | C5: 118 | D5: 37 | E5: 11 | F5: 13 | G5: 14 | K5: S | L5: =C5+C11 -> 159 | M5: =D5+D11 -> 76 | N5: =E5+E11 -> 15 | O5: =F5+F11 -> 31 | P5: =G5+G11 -> 36
B6: M | C6: 16 | D6: 12 | E6: 23 | F6: - | G6: - | K6: M | L6: =C6+C12 -> 65 | M6: =D6+D12 -> 37 | N6: =E6+E12 -> 35
B8: SUR | C8: LATEX | D8: NITRILO | K8: TOTAL | L8: LATEX | M8: NITRILO
D9: AZUL | E9: NEGRO | F9: MORADO | G9: ROSADO
B10: XS | C10: 33 | D10: 30 | E10: 11 | F10: 8 | G10: 29 | K10: XS | L10: =L4 -> 79 | M10: =M4+N4+O4+P4 -> 159
B11: S | C11: 41 | D11: 39 | E11: 4 | F11: 18 | G11: 22 | K11: S | L11: =L5 -> 159 | M11: =M5+N5+O5+P5 -> 158
B12: M | C12: 49 | D12: 25 | E12: 12 | F12: - | G12: - | K12: M | L12: =L6 -> 65 | M12: =M6+N6+O6+P6 -> 72

Sheet tempo norte pedido nuria
A1: pedi junio 28 | B1: referencias | E1: PEDIDO SUR | F1: PEDIDO NORTE | H1: INVENT SUR mar 21 | I1: INVENT NTE
A2: anestesia TOPICA GAROCAINA | F2: 0 | G2: nuria | I2: 0
A3: clorhexidina clorexol 180 ML | F3: 15 | G3: nuria | I3: 6
A4: desinfectantes superficies ORGANICA x 500 ml | F4: 0 | G4: nuria | I4: 8
A5: desinfectantes superficies x 100 ml | F5: 0 | G5: nuria | I5: 18
A6: garhox desinfectantes superficies x 3.850 ml GALON | F6: 0 | G6: nuria | I6: 1
A7: GLUTARALDEHIDO glutarbio x 500 ml organica | B7: MEDIO LITRO | F7: 0 | G7: nuria | I7: 15
A8: Glutaraldehido x 3.850 ml galon organica GRANDE | B8: GALON | C8: AGOTADO | F8: 5 | G8: nuria | I8: 0
A9: Hexitec clorhexidinal clorexol | F9: 15 | G9: nuria | I9: 6
A10: Jabon Enzimatico x 120ml DE ORGANICA | B10: PROQUIDENT $5280 PRODONT $6993 GARHOX $8500 | F10: 0 | G10: NURIA | I10: 23
A11: jabon enzimatico x 500 cc organica | F11: 0 | G11: nuria | I11: 16
A12: Jabon Enzimatico x GALON DE ORGANICA | F12: 1 | G12: nuria | I12: 0

Sheet tempo pedido norte soccidentale
A1: pedi junio 28 | B1: referencias | E1: PEDIDO SUR | F1: PEDIDO NORTE | H1: INVENT SUR mar 21 | I1: INVENT NTE
A2: Aceite LUBRICANTE X200 ML Maquira | F2: 0 | G2: SOCCIDENTALES | I2: 0
A3: acido desmineralizante 37% fosforico MAQUIRA 2.5 | B3: ACIDO | C3: PRECIO MAYO 20 | F3: 0 | G3: RAMON CLAUDIA SOCCIDENTALES | I3: 30
A4: acido fluorhidrico 10% Jeringa 2.5 ml Maquira | F4: 6 | G4: SOCCIDENTALES CLAUDIA | I4: 4
A5: Aclaramiento casero Power bleaching bM4 16 % | F5: 0 | G5: SOCCIDENTALES | I5: 10
A6: Aclaramiento casero Power bleaching bM4 22 % | F6: 0 | G6: SOCCIDENTALES | I6: 0
A7: Adhesivo bond 2.1 4ml maquira | B7: SOCCIDEN $22000 | F7: 0 | G7: SOCCIDENTALES CLAUDIA | I7: 6
A8: Adhesivo bond 2.1 5ml maquira | F8: 0 | G8: SOCCIDENTALES CLAUDIA | I8: 0
A9: Adhesivo bond 2.1 6ml maquira | F9: 0 | G9: SOCCIDENTALES CLAUDIA | I9: 0
A10: Apacal Art x2 jeringas | F10: 0 | G10: SOCCIDENTALES | I10: 0
A11: Barrera Gingival Max Dam Jeringa 2 g Maquira | B11: COMPRE 17600 | C11: PRECIO 20 MAYO | F11: 0 | G11: RAMON SOCCIDENTALES CLAUDIA | I11: 7
A12: base it Cemento base intermedia Spident | F12: 3 | G12: SOCCIDENTALES | I12: 2
A13: cemento fostato de zinc | F13: 0 | G13: SOCCIDENTALES CLAUDIA | I13: 0
A14: cemento resinoso Dual Force 5g maquira | B14: compre $0 | F14: 0 | G14: RAMON SOCCIDENTALES CLAUDIA | I14: 0
A15: cemento temporal TEMP IT FLOW eringa X 2 GM | F15: 0 | G15: RAMON SOCCIDENTALES CLAUDIA | I15: 2
A16: cemento temporal TEMP IT jeringa X 3 GM | F16: 0 | G16: RAMON SOCCIDENTALES CLAUDIA | I16: 0
A17: cemento temporal Applic 2g maquira x 2 jeringas | F17: 0 | G17: RAMON SOCCIDENTALES CLAUDIA | I17: 8
A18: Cemento temporal fluor OBTUR 25 gm | F18: 10 | G18: soccidentales | I18: 5
A19: Cemento Temporal Orafil G x 40gr prevest | F19: 0 | G19: soccidentales | I19: 0
A20: Conos de Gutapercha No 15 caja x 6 | B20: ABRA $ //15,500 // DAZA $ 16,700 //SOCCID $14500 | F20: 0 | G20: ABRAHAM DAZA SOCCIDENTALES | I20: 15
A21: Conos de Gutapercha No 20 caja x 6 | B21: ABRA $ //15,500 // DAZA $ 16,700 //SOCCID $14500 | F21: 0 | G21: ABRAHAM DAZA SOCCIDENTALES | I21: 12
A22: Conos de Gutapercha No 25 caja x 6 | B22: ABRA $ //15,500 // DAZA $ 16,700 //SOCCID $14500 | F22: 3 | G22: ABRAHAM DAZA SOCCIDENTALES | I22: 1
A23: Conos de Gutapercha No 30 caja x 6 | B23: ABRA $ //15,500 // DAZA $ 16,700 //SOCCID $14500 | F23: 0 | G23: ABRAHAM DAZA SOCCIDENTALES | I23: 4
A24: Conos de Gutapercha No 35 caja x 6 | B24: ABRA $ //15,500 // DAZA $ 16,700 //SOCCID $14500 | F24: 0 | G24: ABRAHAM DAZA SOCCIDENTALES | I24: 5
A25: Conos de Gutapercha No 40 caja x 6 | B25: ABRA $ //15,500 // DAZA $ 16,700 //SOCCID $14500 | F25: 0 | G25: ABRAHAM DAZA SOCCIDENTALES | I25: 8
A26: Conos de Gutapercha 15-40 1ra serie | B26: ABRA $ //15,500 // DAZA $ 16,700 //SOCCID $14500 | F26: 0 | G26: ABRAHAM DAZA SOCCIDENTALES | I26: 12
A27: Conos de Gutapercha 45-80 2da serie | B27: ABRA $ //15,500 // DAZA $ 16,700 //SOCCID $14500 | F27: 0 | G27: ABRAHAM DAZA SOCCIDENTALES | I27: 9
A28: Endo ice spray 200ML | F28: 0 | G28: RAMON SOCCIDENTALES ultradental | I28: 7
A29: ESTEMP NE spident tembond 2jeringas x 10gr | F29: 0 | G29: SOCCIDENTALES | I29: 0
A30: fix RESINA ortodoncia 2.5ml | B30: ortho $35000 | F30: 0 | G30: SOCCIDENTALES CLAUDIA ortho prof | I30: 12
A31: GELATAM HEMOSPON CAJA X 40U | F31: 0 | G31: soccidentales | I31: 4
A32: GELATAM HEMOSPON tira X 10 | F32: 0 | G32: soccidentales | I32: 0
A33: GELATAM HEMOSPON unidad | F33: 0 | G33: soccidentales | I33: 0
A34: hidroxcal hidroxido de calcio FOTOCURADO 2gm | F34: 0 | G34: SOCCIDENTALES CLAUDIA | I34: 0
A35: Hilo retractor 00 no impregnado maquira | F35: 0 | G35: SOCCIDENTALES CLAUDIA | I35: 0
A36: Hilo retractor 000 no impregnado maquira | F36: 0 | G36: SOCCIDENTALES CLAUDIA | I36: 0
A37: hydcal hidcal dycal cemento hidroxido calcio pasta pasta | F37: 0 | G37: SOCCIDENTALES | I37: 4
A38: ionomero cementante IONGLASS C | B38: COMPRE 49900 | F38: 0 | G38: SOCCIDENTALES | I38: 0
A39: Marcador plastico caucho instrumental autoclavable | B39: IMPORT $7122 BRASIL SOCCI | F39: 0 | G39: SOCCIDENTALES CLAUDIA | I39: 0
A40: matriz universal kit x 25 unidades | F40: 0 | G40: soccidentales abraham importado | I40: 0
...

Sheet PAGO RECIBOS 2025
A1: PAGAR ANTES DE: | B1: Clase de Servicio | C1: de que casa | D1: Valor Aprox | E1: Referencia de pago | F1: Agt - 2024 | G1: Sep - 2024 | H1: 45566 | I1: 45597 | J1: 45627 | K1: 45658 | L1: 45690 | M1: 45719 | N1: 45751 | O1: 45782 | P1: 45814 | Q1: 45845 | R1: 45877 | S1: 45909 | T1: 45940 | U1: 45962 | V1: 45993
A2: 1 | B2: ARRENDO UNIDENTAL SUR | C2: UNIDENTAL SUR | D2: 2000000 | G2: SEP 4 $2.000.000 | H2: OCT 04 $2,000,000 | I2: NOV 07 $2,000,000 | J2: DIC 06 $2,000,000 | K2: ENE 10 $2,000,000 | L2: FEB 03 $2,000,000 | M2: MARZO 04 $2,000,000 | N2: ABRIL 04 $2,000,000 | O2: MAYO 05 $2,000,000 | P2: JUNIO 06 $2,167,000
A3: 1 | B3: BANCOOMEVA ASOCIADO | C3: BANCOOMEVA | D3: 4000000 | F3: AGOSTO 1 $2.348.713 | G3: SEP 05 $2,536,275 | H3: OCT 04 $4,700,470 | I3: NOV 05 $2,504,652 | J3: DIC 5 $2,592,022 | K3: ENE 08 $5,401,000 | L3: FEB 05 $1,719,970 | M3: MARZO 05 $4,842,704 | N3: ABRIL 10 $3,290,000 | O3: MAYO 03 $3,252,764 | P3: JUNIO 06 $5,770,000 pago jose
A4: 2 | B4: JOSE DAVID | D4: 600000 | F4: 300000 | G4: 800000 | H4: 700
A5: 2 | B5: GABRIELA | D5: 250000 | F5: 200000 | G5: 400000 | H5: 500
A6: 3 | B6: CELULAR RAUL | C6: MOVISTAR | D6: 45000 | F6: Agt 09 $37579 | G6: sept 6 $37,674 | H6: OCT 07 $37,580 | I6: NOV 05 $36,550 | J6: DIC 5 $36,489 | K6: ENE 08 $36,489 | L6: FEB 05 $37,628 | M6: MARZO 04 $36,489 | N6: ABRIL 02 $36,489 | O6: MAYO 03 $36,489 | P6: JUNIO 06 $36,489
A7: 4 | B7: EMCALI | C7: MORICHAL | D7: 300000 | E7: 1610503 | F7: AGT 10 $679.012 | G7: sept 10 $656.025 | H7: OCT 07 $701,032 | I7: Nov 06 $621,873 | J7: DIC 09 $760,562 | K7: ENE 13 $610,037 | L7: FEB 05 $763,799 | M7: MARZO 07 $638,699 | N7: ABRIL 07 $524,481 | O7: MAYO 08 $533,268 | P7: JUNIO 09 $389,320
A8: 4 | B8: MOVISTAR | C8: GRANADA | D8: 90000 | E8: 605 705 10081 | F8: AGT 10 $56.703 | G8: SEPT 9 $86.000 | H8: OCT 07 $80,395 | I8: NOV 06 $52,121 | J8: DIC 09 $53,093 | K8: ENE 13 $82,457 | L8: FEB 05 $119,965 | M8: MARZO 07 $97,985 | N8: ABRIL 07 $131,636 | O8: MAYO 08 $99,375 | P8: JUNIO 09 $128,849
A9: 5 | B9: EPS JENNIFER MADRID | C9: Mariana gestores 077-000264-71 | D9: 401300 | F9: - | G9: - | H9: - | I9: - | J9: DIC 14 $367,800 | K9: ENE 13 $367,800 | L9: FEB 07 $367,800 | M9: MARZO 08 $401,300 | N9: ABRIL 07 $401,300 | O9: MAYO 08 $401300 | P9: JUNIO 09 $401,300
A10: 6 | B10: RAFA EPS | C10: Mariana gestores 077-000264-71 | D10: 381300 | E10: 8833 68 1550 | F10: AGT 10 $348.000 | G10: sep 10 $348,000 | H10: OCT 08 $348,000 | I10: NOV 07 $348,000 | J10: DIC 14 $348,000 | K10: ENE 13 $348,000 | L10: FEB 07 $348,000 | M10: MARZO 08 $381,300 | N10: ABRIL 07 $381,300 | O10: MAYO 08 $381300 | P10: JUNIO 09 $381,300
A11: 7 | B11: ADMINISTRACION LA CEIBA - Av villas | C11: VALLE LILI 3202 cll 54 #83c2 38 | D11: 172000 | E11: 213002942 | F11: Agt 10 $151.800 | G11: Sep 10 $151,800 | H11: OCT 07 $151,800 | I11: NOV 08 $151,800 | J11: DIC 09 $151,800 | K11: ENE 09 $151,800 | L11: FEB 10 $151,800 | M11: MARZO 08 $151,800 | N11: ABRIL 07 $232,600 | O11: MAYO 09 $172,000 | P11: JUNIO 09 $172,000
A12: 7 | B12: ADMINISTRACION AV Villas | C12: URBANIZ CERROS Cll 1 #56-70 | D12: 530100 | F12: pago 10 Agt 2024 $460750 | G12: Sep 10 $460,750 | H12: OCT 08 $460,750 | I12: NOV 08 $460,750 | J12: DIC 09 $460,750 | K12: ENE 09 $460,750 | L12: FEB 10 $460,750 | M12: MARZO 08 $460,750 | N12: ABRIL 08 $740,100 | O12: MAYO 09 $530,100 | P12: JUNIO 06 $530,100
A13: 10 | B13: EPS - Simple | C13: RAUL | D13: 405800 | E13: 883 368 1550 | F13: Agoto 12 $370.500 | G13: Sep 10 $370,500 | H13: OCT 08 $370,500 | I13: NOV 26 $371,900 | J13: DIC 16 $370,500 | K13: ENE 14 $370,500 | L13: ENE 16 $405,800 | M13: MARZO 11 $405,800 | N13: ABRIL 08 $405,800 | O13: MAYO 12 $405,800 | P13: JUNIO 09 $405,800
A14: 15 | B14: GASES DE OCCIDENTE | C14: VALLE LILI | D14: 25000 | E14: 1719297 | F14: - | G14: - | H14: - | I14: - | J14: - | K14: - | L14: - | M14: - | N14: - | O14: - | P14: - | Q14: - | R14: - | S14: - | T14: - | U14: - | V14: -
A15: 15 | B15: GASES DE OCCIDENTE | C15: CERROS | D15: 30000 | E15: 641483 | F15: agosto 20 $42.667 | G15: Sep 19 $45,035 | H15: OCT 11 $51,814 | I15: NOV 14 $60,672 | J15: DIC 16 $69,307 | K15: ENE 14 $57,431 | L15: FEB 17 $62,329 | M15: MAR 18 $56,134 | N15: ABRIL 16 $44,317 | O15: MAYO 20 $49,951 | P15: JUNIO 17 $45,171
A16: 17 | B16: CLARO HOGAR | C16: CERROS | D16: 120000 | E16: 7328582 | F16: agosto 20 $92.139 | G16: Sep 19 $99,619 | H16: OCT 11 $99,619 | I16: NOV 14 $106,499 | J16: DIC 17 $106,499 | K16: ENE 16 $106,499 | L16: FEB 20 $106,499 | M16: MARZO 18 $109,499 | N16: ABRIL 23 $106,499 | O16: MAYO 20 $129,198 | P16: junio 17 dice que ya esta cancelada
A17: 17 | B17: MOVISTAR | C17: UNIDENTAL SUR | D17: 100000 | E17: 6074357576 | F17: AGT $50,000 | G17: Sep 19 $156,024 | H17: OCT 17 $137,177 | I17: NOV 14 $137,238 | J17: DIC 17 $89,205 | K17: ENE 16 $89,205 | L17: FEB 20 $88,456 | M17: MARZO 18 $90,539 | N17: ABRIL 16 $89,205 | O17: MAYO 20 $89,205 | P17: JUNIO 17 $150,519
A18: 18 | B18: CREDITO CONSUMO COLPATRIA | C18: RAUL CREDITO | D18: $16,860,000 | E18: 407419259669 | F18: - | G18: - | H18: - | I18: NOV 25 $1,491,000 | J18: DIC 18 $1,589,200 | K18: ENE 16 $1,585,000 | L18: FEB 20 $7,085,000 | M18: MARZO 15 $1,569,183
